Workbook

Sheet Summary
A1: CH28 Software Quality Insight: Summary of results
A2: Business question: which software metrics are associated with modules that have more defects? Data: synthetic (Python, seed 42). Every number below is a formula.
A4: Key figures
A5: Modules analysed | B5: =COUNTA(Modules!$A$2:$A$48) -> 47
A6: Module-release rows | B6: =COUNTA(Data!$A$2:$A$236) -> 235
A7: Total defects | B7: =SUM(Data!$S$2:$S$236) -> 285
A8: Average defects per module-release | B8: =AVERAGE(Data!$S$2:$S$236) -> 1.212766
A9: Repeat-defect modules (defects in 4+ of 5 releases) | B9: =SUM(Modules!$L$2:$L$48) -> 16
A10: High-churn threshold (75th percentile, changed lines) | B10: =Churn!C13 -> 397.35
A12: Findings by business question
A13: Question | B13: Key result | C13: Detail sheet
A14: Q1 Which modules have more defects? | B14: ="The top 10 of "&B5&" modules hold "&TEXT(Defects_by_Module!E15,"0.0%")&" of all "&B7&" defects. By component, "&INDEX(Defects_by_Module!$A$20:$A$25,MATCH(MAX(Defects_by_Module!$C$20:$C$25),Defects_by_Module!$C$20:$C$25,0))&" has the most ("&MAX(Defects_by_Module!$C$20:$C$25)&") and "&INDEX(Defects_by_Module!$A$20:$A$25,MATCH(MIN(Defects_by_Module!$C$20:$C$25),Defects_by_Module!$C$20:$C$25,0))&" the fewest ("&MIN(Defects_by_Module!$C$20:$C$25)&")." -> The top 10 of 47 modules hold 58.2% of all 285 defects. By component, UI has the most (70) and Auth the fewest (31). | C14: Defects_by_Module
A15: Q2 How does complexity relate to defects? | B15: ="Correlation "&TEXT(Complexity!B5,"0.00")&". Defects stay low in the lower half and rise in the top quartile: "&TEXT(Complexity!E14,"0.00")&" defects per release vs "&TEXT(Complexity!E11,"0.00")&" in the lowest quartile ("&TEXT(Complexity!E16,"0.0")&" times)." -> Correlation 0.35. Defects stay low in the lower half and rise in the top quartile: 2.27 defects per release vs 0.76 in the lowest quartile (3.0 times). | C15: Complexity
A16: Q3 Does code churn relate to quality? | B16: ="Yes, it is the strongest metric: correlation "&TEXT(Churn!B5,"0.00")&". The highest-churn quartile averages "&TEXT(Churn!E14,"0.00")&" defects per release vs "&TEXT(Churn!E11,"0.00")&" in the lowest ("&TEXT(Churn!E16,"0.0")&" times)." -> Yes, it is the strongest metric: correlation 0.65. The highest-churn quartile averages 2.73 defects per release vs 0.47 in the lowest (5.8 times). | C16: Churn
A17: Q4 How does test coverage differ? | B17: ="Correlation "&TEXT(Coverage!B4,"0.00")&". Rows with coverage up to 40% average "&TEXT(Coverage!E11,"0.00")&" defects vs "&TEXT(Coverage!E14,"0.00")&" above 80%. The top-10 defect modules average "&TEXT(Coverage!B29,"0.0")&"% coverage vs "&TEXT(Coverage!B30,"0.0")&"% for the rest." -> Correlation -0.39. Rows with coverage up to 40% average 3.68 defects vs 0.62 above 80%. The top-10 defect modules average 49.2% coverage vs 67.2% for the rest. | C17: Coverage
A18: Q5 Which components show repeated defects? | B18: =Component_Trend!C23&" of "&Component_Trend!B23&" modules had defects in 4 or more of 5 releases; "&INDEX(Component_Trend!$A$17:$A$22,MATCH(MAX(Component_Trend!$C$17:$C$22),Component_Trend!$C$17:$C$22,0))&" has the most ("&MAX(Component_Trend!C17:C22)&"). Total defects fell from "&Component_Trend!B11&" in v1.0 to "&Component_Trend!E11&" in v2.1, then rose to "&Component_Trend!F11&" in v3.0." -> 16 of 47 modules had defects in 4 or more of 5 releases; UI has the most (4). Total defects fell from 88 in v1.0 to 37 in v2.1, then rose to 57 in v3.0. | C18: Component_Trend
A19: Q6 Does contributor count relate to defect frequency? | B19: ="Defects rise with contributors (correlation "&TEXT(Contributors!B4,"0.00")&"), but contributors track activity: correlation with commits "&TEXT(Contributors!B6,"0.00")&" and with churn "&TEXT(Contributors!B7,"0.00")&". Churn alone is a stronger signal ("&TEXT(Contributors!B8,"0.00")&")." -> Defects rise with contributors (correlation 0.51), but contributors track activity: correlation with commits 0.88 and with churn 0.79. Churn alone is a stronger signal (0.65). | C19: Contributors
A20: Pivot Tables and Pivot Charts: see the Pivots sheet (six pivot tables with six pivot charts).
A22: Priority tiers (from the risk model and repeat-defect history)
A23: Tier | B23: Modules
A24: Tier 1: fix first | B24: =COUNTIF(Priority_List!$M$5:$M$51,A24) -> 11
A25: Tier 2: watch closely | B25: =COUNTIF(Priority_List!$M$5:$M$51,A25) -> 13
A26: Tier 3: monitor | B26: =COUNTIF(Priority_List!$M$5:$M$51,A26) -> 23
A28: Tier 1 modules: review and test these first
A29: Module | B29: Component | C29: Releases with defects | D29: Avg churn / v3.0 churn | E29: Test coverage v3.0 (%) | F29: Recommended action
A30: =Priority_List!A5 -> payments_fraud | B30: =Priority_List!B5 -> Payments | C30: =Priority_List!E5 -> 4 | D30: =Priority_List!F5 -> 454.2 | E30: =Priority_List!H5 -> 30.7 | F30: =Priority_List!I5 -> Code review + more tests
A31: =Priority_List!A6 -> ui_themes | B31: =Priority_List!B6 -> UI | C31: =Priority_List!E6 -> 4 | D31: =Priority_List!F6 -> 529 | E31: =Priority_List!H6 -> 57.6 | F31: =Priority_List!I6 -> Code review + more tests
A32: =Priority_List!A7 -> reporting_audit_logs | B32: =Priority_List!B7 -> Reporting | C32: =Priority_List!E7 -> 5 | D32: =Priority_List!F7 -> 773.4 | E32: =Priority_List!H7 -> 62.4 | F32: =Priority_List!I7 -> Priority code review
A33: =Priority_List!A8 -> reporting_scheduler | B33: =Priority_List!B8 -> Reporting | C33: =Priority_List!E8 -> 5 | D33: =Priority_List!F8 -> 262.5 | E33: =Priority_List!H8 -> 41.05 | F33: =Priority_List!I8 -> Add tests
A34: =Priority_List!A9 -> api_gateway | B34: =Priority_List!B9 -> API | C34: =Priority_List!E9 -> 5 | D34: =Priority_List!F9 -> 455.5 | E34: =Priority_List!H9 -> 41.1 | F34: =Priority_List!I9 -> Code review + more tests
A35: =Priority_List!A10 -> api_webhooks | B35: =Priority_List!B10 -> API | C35: =Priority_List!E10 -> 4 | D35: =Priority_List!F10 -> 100.2 | E35: =Priority_List!H10 -> 29.5 | F35: =Priority_List!I10 -> Add tests
A36: =Priority_List!A11 -> reporting_export | B36: =Priority_List!B11 -> Reporting | C36: =Priority_List!E11 -> 4 | D36: =Priority_List!F11 -> 399 | E36: =Priority_List!H11 -> 61.8 | F36: =Priority_List!I11 -> Priority code review
A37: =Priority_List!A12 -> ui_notifications | B37: =Priority_List!B12 -> UI | C37: =Priority_List!E12 -> 4 | D37: =Priority_List!F12 -> 593.4 | E37: =Priority_List!H12 -> 35.4 | F37: =Priority_List!I12 -> Code review + more tests
A38: =Priority_List!A13 -> auth_session | B38: =Priority_List!B13 -> Auth | C38: =Priority_List!E13 -> 5 | D38: =Priority_List!F13 -> 167.9 | E38: =Priority_List!H13 -> 47.2 | F38: =Priority_List!I13 -> Add tests
A39: =Priority_List!A14 -> ui_charts | B39: =Priority_List!B14 -> UI | C39: =Priority_List!E14 -> 4 | D39: =Priority_List!F14 -> 214.1 | E39: =Priority_List!H14 -> 58.9 | F39: =Priority_List!I14 -> Add tests
A40: =Priority_List!A15 -> database_migration | B40: =Priority_List!B15 -> Database | C40: =Priority_List!E15 -> 5 | D40: =Priority_List!F15 -> 150.5 | E40: =Priority_List!H15 -> 54.7 | F40: =Priority_List!I15 -> Add tests
A42: Recommendations
A43: ="1. Put the "&B24&" Tier 1 modules under mandatory code review and raise their test coverage to at least 60% first; coverage below 60% is where defects rise sharply." -> 1. Put the 11 Tier 1 modules under mandatory code review and raise their test coverage to at least 60% first; coverage below 60% is where defects rise sharply.
A44: ="2. Add a review trigger for churn spikes: any module with more than about "&TEXT(B10,"0")&" changed lines in a release (top quartile) gets a mandatory review, even if coverage looks healthy." -> 2. Add a review trigger for churn spikes: any module with more than about 397 changed lines in a release (top quartile) gets a mandatory review, even if coverage looks healthy.
A45: ="3. Track the "&B9&" repeat-defect modules each release and watch "&INDEX(Component_Trend!$A$17:$A$22,MATCH(MAX(Component_Trend!$C$17:$C$22),Component_Trend!$C$17:$C$22,0))&" and the v3.0 rebound (total defects "&Component_Trend!E11&" in v2.1 vs "&Component_Trend!F11&" in v3.0)." -> 3. Track the 16 repeat-defect modules each release and watch UI and the v3.0 rebound (total defects 37 in v2.1 vs 57 in v3.0).
...

Sheet Defects_by_Module
A1: Q1. Which modules have more defects?
A2: All values are formulas on the Data and Modules sheets.
A3: Top 10 modules by total defects (all releases)
A4: Rank | B4: Module | C4: Component | D4: Total defects | E4: Share of all defects | F4: Releases with defects | G4: Avg coverage (%) | H4: Priority tier
A5: 1 | B5: =INDEX(Modules!$A$2:$A$48,MATCH($A5,Modules!$M$2:$M$48,0)) -> api_gateway | C5: =INDEX(Modules!$B$2:$B$48,MATCH($A5,Modules!$M$2:$M$48,0)) -> API | D5: =INDEX(Modules!$E$2:$E$48,MATCH($A5,Modules!$M$2:$M$48,0)) -> 29 | E5: =D5/SUM(Modules!$E$2:$E$48) -> 0.10175439 | F5: =INDEX(Modules!$J$2:$J$48,MATCH($A5,Modules!$M$2:$M$48,0)) -> 5 | G5: =INDEX(Modules!$H$2:$H$48,MATCH($A5,Modules!$M$2:$M$48,0)) -> 41.04 | H5: =INDEX(Modules!$N$2:$N$48,MATCH($A5,Modules!$M$2:$M$48,0)) -> Tier 1: fix first
A6: 2 | B6: =INDEX(Modules!$A$2:$A$48,MATCH($A6,Modules!$M$2:$M$48,0)) -> ui_notifications | C6: =INDEX(Modules!$B$2:$B$48,MATCH($A6,Modules!$M$2:$M$48,0)) -> UI | D6: =INDEX(Modules!$E$2:$E$48,MATCH($A6,Modules!$M$2:$M$48,0)) -> 25 | E6: =D6/SUM(Modules!$E$2:$E$48) -> 0.087719298 | F6: =INDEX(Modules!$J$2:$J$48,MATCH($A6,Modules!$M$2:$M$48,0)) -> 4 | G6: =INDEX(Modules!$H$2:$H$48,MATCH($A6,Modules!$M$2:$M$48,0)) -> 33.14 | H6: =INDEX(Modules!$N$2:$N$48,MATCH($A6,Modules!$M$2:$M$48,0)) -> Tier 1: fix first
A7: 3 | B7: =INDEX(Modules!$A$2:$A$48,MATCH($A7,Modules!$M$2:$M$48,0)) -> ui_themes | C7: =INDEX(Modules!$B$2:$B$48,MATCH($A7,Modules!$M$2:$M$48,0)) -> UI | D7: =INDEX(Modules!$E$2:$E$48,MATCH($A7,Modules!$M$2:$M$48,0)) -> 19 | E7: =D7/SUM(Modules!$E$2:$E$48) -> 0.066666667 | F7: =INDEX(Modules!$J$2:$J$48,MATCH($A7,Modules!$M$2:$M$48,0)) -> 4 | G7: =INDEX(Modules!$H$2:$H$48,MATCH($A7,Modules!$M$2:$M$48,0)) -> 55.52 | H7: =INDEX(Modules!$N$2:$N$48,MATCH($A7,Modules!$M$2:$M$48,0)) -> Tier 1: fix first
A8: 4 | B8: =INDEX(Modules!$A$2:$A$48,MATCH($A8,Modules!$M$2:$M$48,0)) -> auth_session | C8: =INDEX(Modules!$B$2:$B$48,MATCH($A8,Modules!$M$2:$M$48,0)) -> Auth | D8: =INDEX(Modules!$E$2:$E$48,MATCH($A8,Modules!$M$2:$M$48,0)) -> 17 | E8: =D8/SUM(Modules!$E$2:$E$48) -> 0.059649123 | F8: =INDEX(Modules!$J$2:$J$48,MATCH($A8,Modules!$M$2:$M$48,0)) -> 5 | G8: =INDEX(Modules!$H$2:$H$48,MATCH($A8,Modules!$M$2:$M$48,0)) -> 36.74 | H8: =INDEX(Modules!$N$2:$N$48,MATCH($A8,Modules!$M$2:$M$48,0)) -> Tier 1: fix first
A9: 5 | B9: =INDEX(Modules!$A$2:$A$48,MATCH($A9,Modules!$M$2:$M$48,0)) -> payments_fraud | C9: =INDEX(Modules!$B$2:$B$48,MATCH($A9,Modules!$M$2:$M$48,0)) -> Payments | D9: =INDEX(Modules!$E$2:$E$48,MATCH($A9,Modules!$M$2:$M$48,0)) -> 15 | E9: =D9/SUM(Modules!$E$2:$E$48) -> 0.052631579 | F9: =INDEX(Modules!$J$2:$J$48,MATCH($A9,Modules!$M$2:$M$48,0)) -> 4 | G9: =INDEX(Modules!$H$2:$H$48,MATCH($A9,Modules!$M$2:$M$48,0)) -> 37.76 | H9: =INDEX(Modules!$N$2:$N$48,MATCH($A9,Modules!$M$2:$M$48,0)) -> Tier 1: fix first
A10: 6 | B10: =INDEX(Modules!$A$2:$A$48,MATCH($A10,Modules!$M$2:$M$48,0)) -> reporting_audit_logs | C10: =INDEX(Modules!$B$2:$B$48,MATCH($A10,Modules!$M$2:$M$48,0)) -> Reporting | D10: =INDEX(Modules!$E$2:$E$48,MATCH($A10,Modules!$M$2:$M$48,0)) -> 14 | E10: =D10/SUM(Modules!$E$2:$E$48) -> 0.049122807 | F10: =INDEX(Modules!$J$2:$J$48,MATCH($A10,Modules!$M$2:$M$48,0)) -> 5 | G10: =INDEX(Modules!$H$2:$H$48,MATCH($A10,Modules!$M$2:$M$48,0)) -> 63.26 | H10: =INDEX(Modules!$N$2:$N$48,MATCH($A10,Modules!$M$2:$M$48,0)) -> Tier 1: fix first
A11: 7 | B11: =INDEX(Modules!$A$2:$A$48,MATCH($A11,Modules!$M$2:$M$48,0)) -> reporting_scheduler | C11: =INDEX(Modules!$B$2:$B$48,MATCH($A11,Modules!$M$2:$M$48,0)) -> Reporting | D11: =INDEX(Modules!$E$2:$E$48,MATCH($A11,Modules!$M$2:$M$48,0)) -> 13 | E11: =D11/SUM(Modules!$E$2:$E$48) -> 0.045614035 | F11: =INDEX(Modules!$J$2:$J$48,MATCH($A11,Modules!$M$2:$M$48,0)) -> 5 | G11: =INDEX(Modules!$H$2:$H$48,MATCH($A11,Modules!$M$2:$M$48,0)) -> 41.03 | H11: =INDEX(Modules!$N$2:$N$48,MATCH($A11,Modules!$M$2:$M$48,0)) -> Tier 1: fix first
A12: 8 | B12: =INDEX(Modules!$A$2:$A$48,MATCH($A12,Modules!$M$2:$M$48,0)) -> database_migration | C12: =INDEX(Modules!$B$2:$B$48,MATCH($A12,Modules!$M$2:$M$48,0)) -> Database | D12: =INDEX(Modules!$E$2:$E$48,MATCH($A12,Modules!$M$2:$M$48,0)) -> 12 | E12: =D12/SUM(Modules!$E$2:$E$48) -> 0.042105263 | F12: =INDEX(Modules!$J$2:$J$48,MATCH($A12,Modules!$M$2:$M$48,0)) -> 5 | G12: =INDEX(Modules!$H$2:$H$48,MATCH($A12,Modules!$M$2:$M$48,0)) -> 56.08 | H12: =INDEX(Modules!$N$2:$N$48,MATCH($A12,Modules!$M$2:$M$48,0)) -> Tier 1: fix first
A13: 9 | B13: =INDEX(Modules!$A$2:$A$48,MATCH($A13,Modules!$M$2:$M$48,0)) -> payments_invoice | C13: =INDEX(Modules!$B$2:$B$48,MATCH($A13,Modules!$M$2:$M$48,0)) -> Payments | D13: =INDEX(Modules!$E$2:$E$48,MATCH($A13,Modules!$M$2:$M$48,0)) -> 12 | E13: =D13/SUM(Modules!$E$2:$E$48) -> 0.042105263 | F13: =INDEX(Modules!$J$2:$J$48,MATCH($A13,Modules!$M$2:$M$48,0)) -> 4 | G13: =INDEX(Modules!$H$2:$H$48,MATCH($A13,Modules!$M$2:$M$48,0)) -> 61.28 | H13: =INDEX(Modules!$N$2:$N$48,MATCH($A13,Modules!$M$2:$M$48,0)) -> Tier 3: monitor
A14: 10 | B14: =INDEX(Modules!$A$2:$A$48,MATCH($A14,Modules!$M$2:$M$48,0)) -> database_replication | C14: =INDEX(Modules!$B$2:$B$48,MATCH($A14,Modules!$M$2:$M$48,0)) -> Database | D14: =INDEX(Modules!$E$2:$E$48,MATCH($A14,Modules!$M$2:$M$48,0)) -> 10 | E14: =D14/SUM(Modules!$E$2:$E$48) -> 0.035087719 | F14: =INDEX(Modules!$J$2:$J$48,MATCH($A14,Modules!$M$2:$M$48,0)) -> 5 | G14: =INDEX(Modules!$H$2:$H$48,MATCH($A14,Modules!$M$2:$M$48,0)) -> 65.82 | H14: =INDEX(Modules!$N$2:$N$48,MATCH($A14,Modules!$M$2:$M$48,0)) -> Tier 3: monitor
A15: Top 10 total | D15: =SUM(D5:D14) -> 166 | E15: =D15/SUM(Modules!$E$2:$E$48) -> 0.58245614
A18: Defects by component
A19: Component | B19: Modules | C19: Total defects | D19: Avg defects per module-release | E19: Share of all defects
A20: API | B20: =COUNTIF(Modules!$B$2:$B$48,A20) -> 8 | C20: =SUMIFS(Data!$S$2:$S$236,Data!$B$2:$B$236,A20) -> 50 | D20: =AVERAGEIFS(Data!$S$2:$S$236,Data!$B$2:$B$236,A20) -> 1.25 | E20: =C20/$C$26 -> 0.1754386
A21: Auth | B21: =COUNTIF(Modules!$B$2:$B$48,A21) -> 8 | C21: =SUMIFS(Data!$S$2:$S$236,Data!$B$2:$B$236,A21) -> 31 | D21: =AVERAGEIFS(Data!$S$2:$S$236,Data!$B$2:$B$236,A21) -> 0.775 | E21: =C21/$C$26 -> 0.10877193
A22: Database | B22: =COUNTIF(Modules!$B$2:$B$48,A22) -> 7 | C22: =SUMIFS(Data!$S$2:$S$236,Data!$B$2:$B$236,A22) -> 36 | D22: =AVERAGEIFS(Data!$S$2:$S$236,Data!$B$2:$B$236,A22) -> 1.0285714 | E22: =C22/$C$26 -> 0.12631579
A23: Payments | B23: =COUNTIF(Modules!$B$2:$B$48,A23) -> 8 | C23: =SUMIFS(Data!$S$2:$S$236,Data!$B$2:$B$236,A23) -> 55 | D23: =AVERAGEIFS(Data!$S$2:$S$236,Data!$B$2:$B$236,A23) -> 1.375 | E23: =C23/$C$26 -> 0.19298246
A24: Reporting | B24: =COUNTIF(Modules!$B$2:$B$48,A24) -> 8 | C24: =SUMIFS(Data!$S$2:$S$236,Data!$B$2:$B$236,A24) -> 43 | D24: =AVERAGEIFS(Data!$S$2:$S$236,Data!$B$2:$B$236,A24) -> 1.075 | E24: =C24/$C$26 -> 0.15087719
A25: UI | B25: =COUNTIF(Modules!$B$2:$B$48,A25) -> 8 | C25: =SUMIFS(Data!$S$2:$S$236,Data!$B$2:$B$236,A25) -> 70 | D25: =AVERAGEIFS(Data!$S$2:$S$236,Data!$B$2:$B$236,A25) -> 1.75 | E25: =C25/$C$26 -> 0.24561404
A26: All components | B26: =SUM(B20:B25) -> 47 | C26: =SUM(C20:C25) -> 285 | D26: =AVERAGE(Data!$S$2:$S$236) -> 1.212766 | E26: =SUM(E20:E25) -> 1
A29: Defects by severity
A30: Severity | B30: Defects | C30: Share
A31: Low | B31: =SUM(Data!$O$2:$O$236) -> 111 | C31: =B31/$B$35 -> 0.38947368
A32: Medium | B32: =SUM(Data!$P$2:$P$236) -> 91 | C32: =B32/$B$35 -> 0.31929825
A33: High | B33: =SUM(Data!$Q$2:$Q$236) -> 61 | C33: =B33/$B$35 -> 0.21403509
A34: Critical | B34: =SUM(Data!$R$2:$R$236) -> 22 | C34: =B34/$B$35 -> 0.077192982
A35: Total | B35: =SUM(B31:B34) -> 285 | C35: =SUM(C31:C34) -> 1
A38: How many defects does a module have in one release?
A39: Defects in a release | B39: Module-releases
A40: 0 | B40: =COUNTIF(Data!$S$2:$S$236,0) -> 115
A41: 1 | B41: =COUNTIF(Data!$S$2:$S$236,1) -> 53
A42: 2 | B42: =COUNTIF(Data!$S$2:$S$236,2) -> 31
A43: 3 | B43: =COUNTIF(Data!$S$2:$S$236,3) -> 16
A44: 4 | B44: =COUNTIF(Data!$S$2:$S$236,4) -> 8
A45: 5 or more | B45: =COUNTIF(Data!$S$2:$S$236,">=5") -> 12
A46: Total | B46: =SUM(B40:B45) -> 235

Sheet Complexity
A1: Complexity vs defects
A2: Correlation, regression and quartile bands. Quartile boundaries (column C) also drive the band columns on the Data sheet.
A3: Relationship statistics (235 module-release rows)
A4: Observations (n) | B4: =COUNT(Data!$H$2:$H$236) -> 235
A5: Correlation with defects (Pearson r) | B5: =CORREL(Data!$H$2:$H$236,Data!$S$2:$S$236) -> 0.34552546
A6: R-squared | B6: =RSQ(Data!$S$2:$S$236,Data!$H$2:$H$236) -> 0.11938784
A7: Slope (defects per unit) | B7: =SLOPE(Data!$S$2:$S$236,Data!$H$2:$H$236) -> 0.10044594
A8: Intercept | B8: =INTERCEPT(Data!$S$2:$S$236,Data!$H$2:$H$236) -> -0.30118088
A9: Complexity quartile bands
A10: Band | B10: Lower bound (above) | C10: Upper bound (up to) | D10: Module-releases | E10: Avg defects per release | F10: Times the lowest band
A11: Q1 (lowest) | B11: =MIN(Data!$H$2:$H$236) -> 2 | C11: =QUARTILE(Data!$H$2:$H$236,1) -> 10.45 | D11: =COUNTIFS(Data!$H$2:$H$236,"<="&C11) -> 59 | E11: =AVERAGEIFS(Data!$S$2:$S$236,Data!$H$2:$H$236,"<="&C11) -> 0.76271186 | F11: =E11/$E$11 -> 1
A12: Q2 | B12: =C11 -> 10.45 | C12: =QUARTILE(Data!$H$2:$H$236,2) -> 14.96 | D12: =COUNTIFS(Data!$H$2:$H$236,">"&B12,Data!$H$2:$H$236,"<="&C12) -> 59 | E12: =AVERAGEIFS(Data!$S$2:$S$236,Data!$H$2:$H$236,">"&B12,Data!$H$2:$H$236,"<="&C12) -> 0.52542373 | F12: =E12/$E$11 -> 0.68888889
A13: Q3 | B13: =C12 -> 14.96 | C13: =QUARTILE(Data!$H$2:$H$236,3) -> 19.5325 | D13: =COUNTIFS(Data!$H$2:$H$236,">"&B13,Data!$H$2:$H$236,"<="&C13) -> 58 | E13: =AVERAGEIFS(Data!$S$2:$S$236,Data!$H$2:$H$236,">"&B13,Data!$H$2:$H$236,"<="&C13) -> 1.2931034 | F13: =E13/$E$11 -> 1.6954023
A14: Q4 (highest) | B14: =C13 -> 19.5325 | C14: =MAX(Data!$H$2:$H$236) -> 33.4 | D14: =COUNTIFS(Data!$H$2:$H$236,">"&B14,Data!$H$2:$H$236,"<="&C14) -> 59 | E14: =AVERAGEIFS(Data!$S$2:$S$236,Data!$H$2:$H$236,">"&B14,Data!$H$2:$H$236,"<="&C14) -> 2.2711864 | F14: =E14/$E$11 -> 2.9777778
A16: Top quartile vs lowest quartile | E16: =E14/E11 -> 2.9777778
A18: Complexity values above 100 were treated as errors, set to missing and filled with the module median (see Notes).

Sheet Churn
A1: Code churn vs defects
A2: Correlation, regression and quartile bands. Quartile boundaries (column C) also drive the band columns on the Data sheet.
A3: Relationship statistics (235 module-release rows)
A4: Observations (n) | B4: =COUNT(Data!$J$2:$J$236) -> 235
A5: Correlation with defects (Pearson r) | B5: =CORREL(Data!$J$2:$J$236,Data!$S$2:$S$236) -> 0.6451714
A6: R-squared | B6: =RSQ(Data!$S$2:$S$236,Data!$J$2:$J$236) -> 0.41624613
A7: Slope (defects per unit) | B7: =SLOPE(Data!$S$2:$S$236,Data!$J$2:$J$236) -> 0.0055206874
A8: Intercept | B8: =INTERCEPT(Data!$S$2:$S$236,Data!$J$2:$J$236) -> -0.56781197
A9: Code churn quartile bands
A10: Band | B10: Lower bound (above) | C10: Upper bound (up to) | D10: Module-releases | E10: Avg defects per release | F10: Times the lowest band
A11: Q1 (lowest) | B11: =MIN(Data!$J$2:$J$236) -> 33.7 | C11: =QUARTILE(Data!$J$2:$J$236,1) -> 165.2 | D11: =COUNTIFS(Data!$J$2:$J$236,"<="&C11) -> 59 | E11: =AVERAGEIFS(Data!$S$2:$S$236,Data!$J$2:$J$236,"<="&C11) -> 0.47457627 | F11: =E11/$E$11 -> 1
A12: Q2 | B12: =C11 -> 165.2 | C12: =QUARTILE(Data!$J$2:$J$236,2) -> 282 | D12: =COUNTIFS(Data!$J$2:$J$236,">"&B12,Data!$J$2:$J$236,"<="&C12) -> 59 | E12: =AVERAGEIFS(Data!$S$2:$S$236,Data!$J$2:$J$236,">"&B12,Data!$J$2:$J$236,"<="&C12) -> 0.77966102 | F12: =E12/$E$11 -> 1.6428571
A13: Q3 | B13: =C12 -> 282 | C13: =QUARTILE(Data!$J$2:$J$236,3) -> 397.35 | D13: =COUNTIFS(Data!$J$2:$J$236,">"&B13,Data!$J$2:$J$236,"<="&C13) -> 58 | E13: =AVERAGEIFS(Data!$S$2:$S$236,Data!$J$2:$J$236,">"&B13,Data!$J$2:$J$236,"<="&C13) -> 0.86206897 | F13: =E13/$E$11 -> 1.8165025
A14: Q4 (highest) | B14: =C13 -> 397.35 | C14: =MAX(Data!$J$2:$J$236) -> 1249.4 | D14: =COUNTIFS(Data!$J$2:$J$236,">"&B14,Data!$J$2:$J$236,"<="&C14) -> 59 | E14: =AVERAGEIFS(Data!$S$2:$S$236,Data!$J$2:$J$236,">"&B14,Data!$J$2:$J$236,"<="&C14) -> 2.7288136 | F14: =E14/$E$11 -> 5.75
A16: Top quartile vs lowest quartile | E16: =E14/E11 -> 5.75
A18: Churn = changed lines per module-release from metrics data. Churn is the strongest single metric by Pearson correlation.

Sheet Coverage
A1: Q4. How does test coverage differ?
A2: Coverage bands, component comparison and top-10 defect modules vs the rest.
A3: Relationship statistics
A4: Correlation with defects (Pearson r) | B4: =CORREL(Data!$K$2:$K$236,Data!$S$2:$S$236) -> -0.39221355
A5: R-squared | B5: =RSQ(Data!$S$2:$S$236,Data!$K$2:$K$236) -> 0.15383147
A6: Average coverage (%) | B6: =AVERAGE(Data!$K$2:$K$236) -> 63.345106
A9: Average defects by coverage band
A10: Coverage band | B10: Lower bound (above, %) | C10: Upper bound (up to, %) | D10: Module-releases | E10: Avg defects per release
A11: <=40% | B11: 0 | C11: 40 | D11: =COUNTIFS(Data!$K$2:$K$236,">"&B11,Data!$K$2:$K$236,"<="&C11) -> 22 | E11: =AVERAGEIFS(Data!$S$2:$S$236,Data!$K$2:$K$236,">"&B11,Data!$K$2:$K$236,"<="&C11) -> 3.6818182
A12: 40-60% | B12: 40 | C12: 60 | D12: =COUNTIFS(Data!$K$2:$K$236,">"&B12,Data!$K$2:$K$236,"<="&C12) -> 68 | E12: =AVERAGEIFS(Data!$S$2:$S$236,Data!$K$2:$K$236,">"&B12,Data!$K$2:$K$236,"<="&C12) -> 1.4705882
A13: 60-80% | B13: 60 | C13: 80 | D13: =COUNTIFS(Data!$K$2:$K$236,">"&B13,Data!$K$2:$K$236,"<="&C13) -> 124 | E13: =AVERAGEIFS(Data!$S$2:$S$236,Data!$K$2:$K$236,">"&B13,Data!$K$2:$K$236,"<="&C13) -> 0.73387097
A14: 80%+ | B14: 80 | C14: 100 | D14: =COUNTIFS(Data!$K$2:$K$236,">"&B14,Data!$K$2:$K$236,"<="&C14) -> 21 | E14: =AVERAGEIFS(Data!$S$2:$S$236,Data!$K$2:$K$236,">"&B14,Data!$K$2:$K$236,"<="&C14) -> 0.61904762
A15: Lowest band vs highest band | E15: =E11/E14 -> 5.9475524
A18: Coverage and defects by component
A19: Component | B19: Avg test coverage (%) | C19: Avg defects per module-release | D19: Total defects
A20: API | B20: =AVERAGEIFS(Data!$K$2:$K$236,Data!$B$2:$B$236,A20) -> 63.8175 | C20: =AVERAGEIFS(Data!$S$2:$S$236,Data!$B$2:$B$236,A20) -> 1.25 | D20: =SUMIFS(Data!$S$2:$S$236,Data!$B$2:$B$236,A20) -> 50
A21: Auth | B21: =AVERAGEIFS(Data!$K$2:$K$236,Data!$B$2:$B$236,A21) -> 66.695 | C21: =AVERAGEIFS(Data!$S$2:$S$236,Data!$B$2:$B$236,A21) -> 0.775 | D21: =SUMIFS(Data!$S$2:$S$236,Data!$B$2:$B$236,A21) -> 31
A22: Database | B22: =AVERAGEIFS(Data!$K$2:$K$236,Data!$B$2:$B$236,A22) -> 66.865714 | C22: =AVERAGEIFS(Data!$S$2:$S$236,Data!$B$2:$B$236,A22) -> 1.0285714 | D22: =SUMIFS(Data!$S$2:$S$236,Data!$B$2:$B$236,A22) -> 36
A23: Payments | B23: =AVERAGEIFS(Data!$K$2:$K$236,Data!$B$2:$B$236,A23) -> 61.12125 | C23: =AVERAGEIFS(Data!$S$2:$S$236,Data!$B$2:$B$236,A23) -> 1.375 | D23: =SUMIFS(Data!$S$2:$S$236,Data!$B$2:$B$236,A23) -> 55
A24: Reporting | B24: =AVERAGEIFS(Data!$K$2:$K$236,Data!$B$2:$B$236,A24) -> 66.45125 | C24: =AVERAGEIFS(Data!$S$2:$S$236,Data!$B$2:$B$236,A24) -> 1.075 | D24: =SUMIFS(Data!$S$2:$S$236,Data!$B$2:$B$236,A24) -> 43
A25: UI | B25: =AVERAGEIFS(Data!$K$2:$K$236,Data!$B$2:$B$236,A25) -> 55.56 | C25: =AVERAGEIFS(Data!$S$2:$S$236,Data!$B$2:$B$236,A25) -> 1.75 | D25: =SUMIFS(Data!$S$2:$S$236,Data!$B$2:$B$236,A25) -> 70
A28: Top-10 defect modules vs all other modules
A29: Avg coverage (%), top-10 defect modules | B29: =AVERAGEIFS(Modules!$H$2:$H$48,Modules!$M$2:$M$48,"<=10") -> 49.167
A30: Avg coverage (%), other modules | B30: =AVERAGEIFS(Modules!$H$2:$H$48,Modules!$M$2:$M$48,">10") -> 67.177027
A31: Gap (percentage points) | B31: =B30-B29 -> 18.010027

Sheet Component_Trend
A1: Q5. Which components show repeated defects?
A2: Total defects by component and release, plus repeat-defect modules (defects in 4 or more of the 5 releases).
A3: Total defects by component and release
A4: Component | B4: v1.0 | C4: v1.1 | D4: v2.0 | E4: v2.1 | F4: v3.0 | G4: Total
A5: API | B5: =SUMIFS(Data!$S$2:$S$236,Data!$B$2:$B$236,$A5,Data!$D$2:$D$236,B$4) -> 17 | C5: =SUMIFS(Data!$S$2:$S$236,Data!$B$2:$B$236,$A5,Data!$D$2:$D$236,C$4) -> 3 | D5: =SUMIFS(Data!$S$2:$S$236,Data!$B$2:$B$236,$A5,Data!$D$2:$D$236,D$4) -> 12 | E5: =SUMIFS(Data!$S$2:$S$236,Data!$B$2:$B$236,$A5,Data!$D$2:$D$236,E$4) -> 3 | F5: =SUMIFS(Data!$S$2:$S$236,Data!$B$2:$B$236,$A5,Data!$D$2:$D$236,F$4) -> 15 | G5: =SUM(B5:F5) -> 50
A6: Auth | B6: =SUMIFS(Data!$S$2:$S$236,Data!$B$2:$B$236,$A6,Data!$D$2:$D$236,B$4) -> 10 | C6: =SUMIFS(Data!$S$2:$S$236,Data!$B$2:$B$236,$A6,Data!$D$2:$D$236,C$4) -> 4 | D6: =SUMIFS(Data!$S$2:$S$236,Data!$B$2:$B$236,$A6,Data!$D$2:$D$236,D$4) -> 6 | E6: =SUMIFS(Data!$S$2:$S$236,Data!$B$2:$B$236,$A6,Data!$D$2:$D$236,E$4) -> 9 | F6: =SUMIFS(Data!$S$2:$S$236,Data!$B$2:$B$236,$A6,Data!$D$2:$D$236,F$4) -> 2 | G6: =SUM(B6:F6) -> 31
A7: Database | B7: =SUMIFS(Data!$S$2:$S$236,Data!$B$2:$B$236,$A7,Data!$D$2:$D$236,B$4) -> 8 | C7: =SUMIFS(Data!$S$2:$S$236,Data!$B$2:$B$236,$A7,Data!$D$2:$D$236,C$4) -> 8 | D7: =SUMIFS(Data!$S$2:$S$236,Data!$B$2:$B$236,$A7,Data!$D$2:$D$236,D$4) -> 6 | E7: =SUMIFS(Data!$S$2:$S$236,Data!$B$2:$B$236,$A7,Data!$D$2:$D$236,E$4) -> 7 | F7: =SUMIFS(Data!$S$2:$S$236,Data!$B$2:$B$236,$A7,Data!$D$2:$D$236,F$4) -> 7 | G7: =SUM(B7:F7) -> 36
A8: Payments | B8: =SUMIFS(Data!$S$2:$S$236,Data!$B$2:$B$236,$A8,Data!$D$2:$D$236,B$4) -> 19 | C8: =SUMIFS(Data!$S$2:$S$236,Data!$B$2:$B$236,$A8,Data!$D$2:$D$236,C$4) -> 11 | D8: =SUMIFS(Data!$S$2:$S$236,Data!$B$2:$B$236,$A8,Data!$D$2:$D$236,D$4) -> 11 | E8: =SUMIFS(Data!$S$2:$S$236,Data!$B$2:$B$236,$A8,Data!$D$2:$D$236,E$4) -> 3 | F8: =SUMIFS(Data!$S$2:$S$236,Data!$B$2:$B$236,$A8,Data!$D$2:$D$236,F$4) -> 11 | G8: =SUM(B8:F8) -> 55
A9: Reporting | B9: =SUMIFS(Data!$S$2:$S$236,Data!$B$2:$B$236,$A9,Data!$D$2:$D$236,B$4) -> 7 | C9: =SUMIFS(Data!$S$2:$S$236,Data!$B$2:$B$236,$A9,Data!$D$2:$D$236,C$4) -> 11 | D9: =SUMIFS(Data!$S$2:$S$236,Data!$B$2:$B$236,$A9,Data!$D$2:$D$236,D$4) -> 5 | E9: =SUMIFS(Data!$S$2:$S$236,Data!$B$2:$B$236,$A9,Data!$D$2:$D$236,E$4) -> 8 | F9: =SUMIFS(Data!$S$2:$S$236,Data!$B$2:$B$236,$A9,Data!$D$2:$D$236,F$4) -> 12 | G9: =SUM(B9:F9) -> 43
A10: UI | B10: =SUMIFS(Data!$S$2:$S$236,Data!$B$2:$B$236,$A10,Data!$D$2:$D$236,B$4) -> 27 | C10: =SUMIFS(Data!$S$2:$S$236,Data!$B$2:$B$236,$A10,Data!$D$2:$D$236,C$4) -> 16 | D10: =SUMIFS(Data!$S$2:$S$236,Data!$B$2:$B$236,$A10,Data!$D$2:$D$236,D$4) -> 10 | E10: =SUMIFS(Data!$S$2:$S$236,Data!$B$2:$B$236,$A10,Data!$D$2:$D$236,E$4) -> 7 | F10: =SUMIFS(Data!$S$2:$S$236,Data!$B$2:$B$236,$A10,Data!$D$2:$D$236,F$4) -> 10 | G10: =SUM(B10:F10) -> 70
A11: All components | B11: =SUM(B5:B10) -> 88 | C11: =SUM(C5:C10) -> 53 | D11: =SUM(D5:D10) -> 50 | E11: =SUM(E5:E10) -> 37 | F11: =SUM(F5:F10) -> 57 | G11: =SUM(G5:G10) -> 285
A12: Change vs previous release | C12: =C11/B11-1 -> -0.39772727 | D12: =D11/C11-1 -> -0.056603774 | E12: =E11/D11-1 -> -0.26 | F12: =F11/E11-1 -> 0.54054054
A15: Repeat-defect modules by component (defects in 4 or more of 5 releases)
A16: Component | B16: Modules | C16: Repeat-defect modules | D16: Share of modules
A17: API | B17: =COUNTIF(Modules!$B$2:$B$48,A17) -> 8 | C17: =COUNTIFS(Modules!$B$2:$B$48,A17,Modules!$L$2:$L$48,1) -> 2 | D17: =C17/B17 -> 0.25
A18: Auth | B18: =COUNTIF(Modules!$B$2:$B$48,A18) -> 8 | C18: =COUNTIFS(Modules!$B$2:$B$48,A18,Modules!$L$2:$L$48,1) -> 1 | D18: =C18/B18 -> 0.125
A19: Database | B19: =COUNTIF(Modules!$B$2:$B$48,A19) -> 7 | C19: =COUNTIFS(Modules!$B$2:$B$48,A19,Modules!$L$2:$L$48,1) -> 3 | D19: =C19/B19 -> 0.42857143
A20: Payments | B20: =COUNTIF(Modules!$B$2:$B$48,A20) -> 8 | C20: =COUNTIFS(Modules!$B$2:$B$48,A20,Modules!$L$2:$L$48,1) -> 3 | D20: =C20/B20 -> 0.375
A21: Reporting | B21: =COUNTIF(Modules!$B$2:$B$48,A21) -> 8 | C21: =COUNTIFS(Modules!$B$2:$B$48,A21,Modules!$L$2:$L$48,1) -> 3 | D21: =C21/B21 -> 0.375
A22: UI | B22: =COUNTIF(Modules!$B$2:$B$48,A22) -> 8 | C22: =COUNTIFS(Modules!$B$2:$B$48,A22,Modules!$L$2:$L$48,1) -> 4 | D22: =C22/B22 -> 0.5
A23: All components | B23: =SUM(B17:B22) -> 47 | C23: =SUM(C17:C22) -> 16 | D23: =C23/B23 -> 0.34042553
A26: Modules by number of releases with defects
A27: Releases with defects | B27: Modules
A28: 0 | B28: =COUNTIF(Modules!$J$2:$J$48,A28) -> 6
A29: 1 | B29: =COUNTIF(Modules!$J$2:$J$48,A29) -> 6
A30: 2 | B30: =COUNTIF(Modules!$J$2:$J$48,A30) -> 13
A31: 3 | B31: =COUNTIF(Modules!$J$2:$J$48,A31) -> 6
A32: 4 | B32: =COUNTIF(Modules!$J$2:$J$48,A32) -> 10
A33: 5 | B33: =COUNTIF(Modules!$J$2:$J$48,A33) -> 6

Sheet Contributors
A1: Q6. Does contributor count relate to defect frequency?
A2: Defects rise with contributors, but contributors move with overall activity (commits, churn).
A3: Relationship statistics
A4: Correlation: contributors vs defects | B4: =CORREL(Data!$M$2:$M$236,Data!$S$2:$S$236) -> 0.51372734
A5: R-squared | B5: =RSQ(Data!$S$2:$S$236,Data!$M$2:$M$236) -> 0.26391578
A6: Correlation: contributors vs commit count | B6: =CORREL(Data!$M$2:$M$236,Data!$L$2:$L$236) -> 0.87719069
A7: Correlation: contributors vs churn | B7: =CORREL(Data!$M$2:$M$236,Data!$J$2:$J$236) -> 0.79102547
A8: Correlation: churn vs defects (for comparison) | B8: =CORREL(Data!$J$2:$J$236,Data!$S$2:$S$236) -> 0.6451714
A11: Average defects by contributor group
A12: Contributor group | B12: Min contributors | C12: Max contributors | D12: Module-releases | E12: Avg defects per release
A13: 1-2 | B13: 1 | C13: 2 | D13: =COUNTIFS(Data!$M$2:$M$236,">="&B13,Data!$M$2:$M$236,"<="&C13) -> 79 | E13: =AVERAGEIFS(Data!$S$2:$S$236,Data!$M$2:$M$236,">="&B13,Data!$M$2:$M$236,"<="&C13) -> 0.49367089
A14: 3-4 | B14: 3 | C14: 4 | D14: =COUNTIFS(Data!$M$2:$M$236,">="&B14,Data!$M$2:$M$236,"<="&C14) -> 108 | E14: =AVERAGEIFS(Data!$S$2:$S$236,Data!$M$2:$M$236,">="&B14,Data!$M$2:$M$236,"<="&C14) -> 1.0462963
A15: 5-6 | B15: 5 | C15: 6 | D15: =COUNTIFS(Data!$M$2:$M$236,">="&B15,Data!$M$2:$M$236,"<="&C15) -> 41 | E15: =AVERAGEIFS(Data!$S$2:$S$236,Data!$M$2:$M$236,">="&B15,Data!$M$2:$M$236,"<="&C15) -> 2.2195122
A16: 7+ | B16: 7 | C16: 99 | D16: =COUNTIFS(Data!$M$2:$M$236,">="&B16,Data!$M$2:$M$236,"<="&C16) -> 7 | E16: =AVERAGEIFS(Data!$S$2:$S$236,Data!$M$2:$M$236,">="&B16,Data!$M$2:$M$236,"<="&C16) -> 6
A18: Note: the 7+ group has very few rows, so its average is not reliable. Contributors correlate strongly with commits and churn, so the link is mostly activity volume.

Sheet Correlations
A1: Which metrics are associated with defects?
A2: Pearson correlations by formula; Spearman values are imported from the Python notebook.
A3: Correlation of each metric with total defects
A4: Metric | B4: Pearson r (formula) | C4: Spearman r (from notebook)
A5: churn | B5: =CORREL(Data!$J$2:$J$236,Data!$S$2:$S$236) -> 0.6451714 | C5: 0.41
A6: changed_lines | B6: =CORREL(Data!$N$2:$N$236,Data!$S$2:$S$236) -> 0.65098098 | C6: 0.41
A7: commit_count | B7: =CORREL(Data!$L$2:$L$236,Data!$S$2:$S$236) -> 0.61380915 | C7: 0.36
A8: contributors | B8: =CORREL(Data!$M$2:$M$236,Data!$S$2:$S$236) -> 0.51372734 | C8: 0.38
A9: complexity | B9: =CORREL(Data!$H$2:$H$236,Data!$S$2:$S$236) -> 0.34552546 | C9: 0.4
A10: coupling | B10: =CORREL(Data!$I$2:$I$236,Data!$S$2:$S$236) -> 0.34325477 | C10: 0.4
A11: size | B11: =CORREL(Data!$G$2:$G$236,Data!$S$2:$S$236) -> 0.24456492 | C11: 0.11
A12: test_coverage | B12: =CORREL(Data!$K$2:$K$236,Data!$S$2:$S$236) -> -0.39221355 | C12: -0.39
A16: Correlation matrix (Pearson)
A17: Metric | B17: complexity | C17: coupling | D17: churn | E17: test_coverage | F17: contributors | G17: commit_count | H17: changed_lines | I17: size | J17: total_defects
A18: complexity | B18: =CORREL(Data!$H$2:$H$236,Data!$H$2:$H$236) -> 1 | C18: =CORREL(Data!$H$2:$H$236,Data!$I$2:$I$236) -> 0.8177468 | D18: =CORREL(Data!$H$2:$H$236,Data!$J$2:$J$236) -> 0.15190511 | E18: =CORREL(Data!$H$2:$H$236,Data!$K$2:$K$236) -> -0.31659566 | F18: =CORREL(Data!$H$2:$H$236,Data!$M$2:$M$236) -> 0.087585358 | G18: =CORREL(Data!$H$2:$H$236,Data!$L$2:$L$236) -> 0.13393407 | H18: =CORREL(Data!$H$2:$H$236,Data!$N$2:$N$236) -> 0.16805624 | I18: =CORREL(Data!$H$2:$H$236,Data!$G$2:$G$236) -> -0.11757406 | J18: =CORREL(Data!$H$2:$H$236,Data!$S$2:$S$236) -> 0.34552546
A19: coupling | B19: =CORREL(Data!$I$2:$I$236,Data!$H$2:$H$236) -> 0.8177468 | C19: =CORREL(Data!$I$2:$I$236,Data!$I$2:$I$236) -> 1 | D19: =CORREL(Data!$I$2:$I$236,Data!$J$2:$J$236) -> 0.21893589 | E19: =CORREL(Data!$I$2:$I$236,Data!$K$2:$K$236) -> -0.29578222 | F19: =CORREL(Data!$I$2:$I$236,Data!$M$2:$M$236) -> 0.1261906 | G19: =CORREL(Data!$I$2:$I$236,Data!$L$2:$L$236) -> 0.18899519 | H19: =CORREL(Data!$I$2:$I$236,Data!$N$2:$N$236) -> 0.23759038 | I19: =CORREL(Data!$I$2:$I$236,Data!$G$2:$G$236) -> -0.087615571 | J19: =CORREL(Data!$I$2:$I$236,Data!$S$2:$S$236) -> 0.34325477
A20: churn | B20: =CORREL(Data!$J$2:$J$236,Data!$H$2:$H$236) -> 0.15190511 | C20: =CORREL(Data!$J$2:$J$236,Data!$I$2:$I$236) -> 0.21893589 | D20: =CORREL(Data!$J$2:$J$236,Data!$J$2:$J$236) -> 1 | E20: =CORREL(Data!$J$2:$J$236,Data!$K$2:$K$236) -> -0.26244966 | F20: =CORREL(Data!$J$2:$J$236,Data!$M$2:$M$236) -> 0.79102547 | G20: =CORREL(Data!$J$2:$J$236,Data!$L$2:$L$236) -> 0.8904827 | H20: =CORREL(Data!$J$2:$J$236,Data!$N$2:$N$236) -> 0.92906906 | I20: =CORREL(Data!$J$2:$J$236,Data!$G$2:$G$236) -> 0.26809512 | J20: =CORREL(Data!$J$2:$J$236,Data!$S$2:$S$236) -> 0.6451714
A21: test_coverage | B21: =CORREL(Data!$K$2:$K$236,Data!$H$2:$H$236) -> -0.31659566 | C21: =CORREL(Data!$K$2:$K$236,Data!$I$2:$I$236) -> -0.29578222 | D21: =CORREL(Data!$K$2:$K$236,Data!$J$2:$J$236) -> -0.26244966 | E21: =CORREL(Data!$K$2:$K$236,Data!$K$2:$K$236) -> 1 | F21: =CORREL(Data!$K$2:$K$236,Data!$M$2:$M$236) -> -0.12491674 | G21: =CORREL(Data!$K$2:$K$236,Data!$L$2:$L$236) -> -0.22122822 | H21: =CORREL(Data!$K$2:$K$236,Data!$N$2:$N$236) -> -0.21216496 | I21: =CORREL(Data!$K$2:$K$236,Data!$G$2:$G$236) -> -0.18444099 | J21: =CORREL(Data!$K$2:$K$236,Data!$S$2:$S$236) -> -0.39221355
A22: contributors | B22: =CORREL(Data!$M$2:$M$236,Data!$H$2:$H$236) -> 0.087585358 | C22: =CORREL(Data!$M$2:$M$236,Data!$I$2:$I$236) -> 0.1261906 | D22: =CORREL(Data!$M$2:$M$236,Data!$J$2:$J$236) -> 0.79102547 | E22: =CORREL(Data!$M$2:$M$236,Data!$K$2:$K$236) -> -0.12491674 | F22: =CORREL(Data!$M$2:$M$236,Data!$M$2:$M$236) -> 1 | G22: =CORREL(Data!$M$2:$M$236,Data!$L$2:$L$236) -> 0.87719069 | H22: =CORREL(Data!$M$2:$M$236,Data!$N$2:$N$236) -> 0.80201955 | I22: =CORREL(Data!$M$2:$M$236,Data!$G$2:$G$236) -> 0.16700065 | J22: =CORREL(Data!$M$2:$M$236,Data!$S$2:$S$236) -> 0.51372734
A23: commit_count | B23: =CORREL(Data!$L$2:$L$236,Data!$H$2:$H$236) -> 0.13393407 | C23: =CORREL(Data!$L$2:$L$236,Data!$I$2:$I$236) -> 0.18899519 | D23: =CORREL(Data!$L$2:$L$236,Data!$J$2:$J$236) -> 0.8904827 | E23: =CORREL(Data!$L$2:$L$236,Data!$K$2:$K$236) -> -0.22122822 | F23: =CORREL(Data!$L$2:$L$236,Data!$M$2:$M$236) -> 0.87719069 | G23: =CORREL(Data!$L$2:$L$236,Data!$L$2:$L$236) -> 1 | H23: =CORREL(Data!$L$2:$L$236,Data!$N$2:$N$236) -> 0.89070762 | I23: =CORREL(Data!$L$2:$L$236,Data!$G$2:$G$236) -> 0.20403122 | J23: =CORREL(Data!$L$2:$L$236,Data!$S$2:$S$236) -> 0.61380915
A24: changed_lines | B24: =CORREL(Data!$N$2:$N$236,Data!$H$2:$H$236) -> 0.16805624 | C24: =CORREL(Data!$N$2:$N$236,Data!$I$2:$I$236) -> 0.23759038 | D24: =CORREL(Data!$N$2:$N$236,Data!$J$2:$J$236) -> 0.92906906 | E24: =CORREL(Data!$N$2:$N$236,Data!$K$2:$K$236) -> -0.21216496 | F24: =CORREL(Data!$N$2:$N$236,Data!$M$2:$M$236) -> 0.80201955 | G24: =CORREL(Data!$N$2:$N$236,Data!$L$2:$L$236) -> 0.89070762 | H24: =CORREL(Data!$N$2:$N$236,Data!$N$2:$N$236) -> 1 | I24: =CORREL(Data!$N$2:$N$236,Data!$G$2:$G$236) -> 0.20270664 | J24: =CORREL(Data!$N$2:$N$236,Data!$S$2:$S$236) -> 0.65098098
A25: size | B25: =CORREL(Data!$G$2:$G$236,Data!$H$2:$H$236) -> -0.11757406 | C25: =CORREL(Data!$G$2:$G$236,Data!$I$2:$I$236) -> -0.087615571 | D25: =CORREL(Data!$G$2:$G$236,Data!$J$2:$J$236) -> 0.26809512 | E25: =CORREL(Data!$G$2:$G$236,Data!$K$2:$K$236) -> -0.18444099 | F25: =CORREL(Data!$G$2:$G$236,Data!$M$2:$M$236) -> 0.16700065 | G25: =CORREL(Data!$G$2:$G$236,Data!$L$2:$L$236) -> 0.20403122 | H25: =CORREL(Data!$G$2:$G$236,Data!$N$2:$N$236) -> 0.20270664 | I25: =CORREL(Data!$G$2:$G$236,Data!$G$2:$G$236) -> 1 | J25: =CORREL(Data!$G$2:$G$236,Data!$S$2:$S$236) -> 0.24456492
A26: total_defects | B26: =CORREL(Data!$S$2:$S$236,Data!$H$2:$H$236) -> 0.34552546 | C26: =CORREL(Data!$S$2:$S$236,Data!$I$2:$I$236) -> 0.34325477 | D26: =CORREL(Data!$S$2:$S$236,Data!$J$2:$J$236) -> 0.6451714 | E26: =CORREL(Data!$S$2:$S$236,Data!$K$2:$K$236) -> -0.39221355 | F26: =CORREL(Data!$S$2:$S$236,Data!$M$2:$M$236) -> 0.51372734 | G26: =CORREL(Data!$S$2:$S$236,Data!$L$2:$L$236) -> 0.61380915 | H26: =CORREL(Data!$S$2:$S$236,Data!$N$2:$N$236) -> 0.65098098 | I26: =CORREL(Data!$S$2:$S$236,Data!$G$2:$G$236) -> 0.24456492 | J26: =CORREL(Data!$S$2:$S$236,Data!$S$2:$S$236) -> 1

Sheet Pivots
A1: Pivot Tables and Pivot Charts
A2: Source: Data!A1:AE236 (one pivot cache shared by all six pivots). Pivot tables on the left, matching pivot charts on the right. Right-click a pivot and choose Refresh (or Data > Refresh All) after changing the Data sheet.
A3: Pivot Table 1: total defects by module
A4: Row Labels | B4: Sum of total_defects
A5: api_gateway | B5: 29
A6: ui_notifications | B6: 25
A7: ui_themes | B7: 19
A8: auth_session | B8: 17
A9: payments_fraud | B9: 15
A10: reporting_audit_logs | B10: 14
A11: reporting_scheduler | B11: 13
A12: database_migration | B12: 12
A13: payments_invoice | B13: 12
A14: database_replication | B14: 10
A15: payments_gateway | B15: 7
A16: reporting_export | B16: 7
... A27: api_docs | B27: 4
A28: api_versioning | B28: 4 | D28: Pivot Table 2: total defects by release and component (component trend)
A29: database_backup | B29: 4 | D29: Sum of total_defects | E29: Column Labels
A30: payments_subscription | B30: 4 | D30: Row Labels | E30: API | F30: Auth | G30: Database | H30: Payments | I30: Reporting | J30: UI | K30: Grand Total
A31: reporting_templates | B31: 4 | D31: v1.0 | E31: 17 | F31: 10 | G31: 8 | H31: 19 | I31: 7 | J31: 27 | K31: 88
A32: ui_forms | B32: 4 | D32: v1.1 | E32: 3 | F32: 4 | G32: 8 | H32: 11 | I32: 11 | J32: 16 | K32: 53
A33: payments_refund | B33: 3 | D33: v2.0 | E33: 12 | F33: 6 | G33: 6 | H33: 11 | I33: 5 | J33: 10 | K33: 50
A34: payments_tax | B34: 3 | D34: v2.1 | E34: 3 | F34: 9 | G34: 7 | H34: 3 | I34: 8 | J34: 7 | K34: 37
A35: ui_dashboard | B35: 3 | D35: v3.0 | E35: 15 | F35: 2 | G35: 7 | H35: 11 | I35: 12 | J35: 10 | K35: 57
A36: ui_navbar | B36: 3 | D36: Grand Total | E36: 50 | F36: 31 | G36: 36 | H36: 55 | I36: 43 | J36: 70 | K36: 285
A37: api_router | B37: 2
A38: auth_oauth | B38: 2
A39: auth_rbac | B39: 2
A40: database_cache | B40: 2
A41: reporting_analytics | B41: 2
A42: reporting_pdfgen | B42: 2
A43: database_indexing | B43: 1
A44: database_pool | B44: 1
A45: reporting_emailer | B45: 1
A46: api_graphql | B46: 0 | D46: Pivot Table 3: average defects by complexity quartile
A47: api_ratelimit | B47: 0 | D47: Row Labels | E47: Average of total_defects
A48: auth_login | B48: 0 | D48: Q1 (lowest) | E48: 0.76271186
A49: auth_mfa | B49: 0 | D49: Q2 | E49: 0.52542373
A50: auth_password | B50: 0 | D50: Q3 | E50: 1.2931034
...

Sheet Priority_List
A1: Module priority list (model output imported from the Python notebook)
A2: Predicted and actual defects are for the latest release (v3.0). Predictions come from unseen-module cross-validation. Tiers combine repeat-defect history with churn and coverage rules (see Notes).
A4: module | B4: component | C4: predicted_defects | D4: actual_defects | E4: releases_with_defects | F4: churn | G4: complexity | H4: test_coverage | I4: action | J4: repeat_defect_module | K4: total_defects_all_releases | L4: avg_risk_score | M4: priority_tier
A5: payments_fraud | B5: Payments | C5: 3.19 | D5: 1 | E5: 4 | F5: 454.2 | G5: 20.06 | H5: 30.7 | I5: Code review + more tests | J5: 1 | K5: 15 | L5: 59.46849 | M5: Tier 1: fix first
A6: ui_themes | B6: UI | C6: 3 | D6: 5 | E6: 4 | F6: 529 | G6: 32.95 | H6: 57.6 | I6: Code review + more tests | J6: 1 | K6: 19 | L6: 60.175221 | M6: Tier 1: fix first
A7: reporting_audit_logs | B7: Reporting | C7: 2 | D7: 5 | E7: 5 | F7: 773.4 | G7: 24.92 | H7: 62.4 | I7: Priority code review | J7: 1 | K7: 14 | L7: 52.161946 | M7: Tier 1: fix first
A8: reporting_scheduler | B8: Reporting | C8: 1.76 | D8: 4 | E8: 5 | F8: 262.5 | G8: 33.4 | H8: 41.05 | I8: Add tests | J8: 1 | K8: 13 | L8: 59.585197 | M8: Tier 1: fix first
A9: api_gateway | B9: API | C9: 1.75 | D9: 5 | E9: 5 | F9: 455.5 | G9: 17.03 | H9: 41.1 | I9: Code review + more tests | J9: 1 | K9: 29 | L9: 57.798232 | M9: Tier 1: fix first
A10: api_webhooks | B10: API | C10: 1.62 | D10: 0 | E10: 4 | F10: 100.2 | G10: 13.69 | H10: 29.5 | I10: Add tests | J10: 1 | K10: 5 | L10: 46.430063 | M10: Tier 1: fix first
A11: reporting_export | B11: Reporting | C11: 1.54 | D11: 3 | E11: 4 | F11: 399 | G11: 17.44 | H11: 61.8 | I11: Priority code review | J11: 1 | K11: 7 | L11: 36.595842 | M11: Tier 1: fix first
A12: ui_notifications | B12: UI | C12: 1.37 | D12: 0 | E12: 4 | F12: 593.4 | G12: 13.31 | H12: 35.4 | I12: Code review + more tests | J12: 1 | K12: 25 | L12: 62.112652 | M12: Tier 1: fix first
A13: auth_session | B13: Auth | C13: 1.07 | D13: 1 | E13: 5 | F13: 167.9 | G13: 19.44 | H13: 47.2 | I13: Add tests | J13: 1 | K13: 17 | L13: 60.15931 | M13: Tier 1: fix first
A14: ui_charts | B14: UI | C14: 0.79 | D14: 1 | E14: 4 | F14: 214.1 | G14: 9.88 | H14: 58.9 | I14: Add tests | J14: 1 | K14: 5 | L14: 36.785016 | M14: Tier 1: fix first
A15: database_migration | B15: Database | C15: 0.73 | D15: 2 | E15: 5 | F15: 150.5 | G15: 17.29 | H15: 54.7 | I15: Add tests | J15: 1 | K15: 12 | L15: 49.426167 | M15: Tier 1: fix first
A16: api_docs | B16: API | C16: 8.55 | D16: 4 | E16: 1 | F16: 1161.8 | G16: 10.27 | H16: 87.4 | I16: Priority code review | J16: 0 | K16: 4 | L16: 26.869784 | M16: Tier 2: watch closely
... A51: payments_subscription | B51: Payments | C51: 0.07 | D51: 0 | E51: 3 | F51: 265.5 | G51: 8.47 | H51: 78.3 | I51: Monitor | J51: 0 | K51: 4 | L51: 29.123828 | M51: Tier 3: monitor

Sheet Modules
A1: module | B1: component | C1: language | D1: size (lines of code) | E1: total_defects | F1: avg_complexity | G1: avg_churn | H1: avg_coverage | I1: avg_contributors | J1: releases_with_defects | K1: defects_per_1000_lines | L1: repeat_defect_module (4+ releases) | M1: defects_rank | N1: priority_tier
A2: api_gateway | B2: API | C2: Java | D2: 2296 | E2: =SUMIFS(Data!$S$2:$S$236,Data!$A$2:$A$236,$A2) -> 29 | F2: =AVERAGEIFS(Data!$H$2:$H$236,Data!$A$2:$A$236,$A2) -> 19.595 | G2: =AVERAGEIFS(Data!$J$2:$J$236,Data!$A$2:$A$236,$A2) -> 513.16 | H2: =AVERAGEIFS(Data!$K$2:$K$236,Data!$A$2:$A$236,$A2) -> 41.04 | I2: =AVERAGEIFS(Data!$M$2:$M$236,Data!$A$2:$A$236,$A2) -> 4.4 | J2: =COUNTIFS(Data!$A$2:$A$236,$A2,Data!$S$2:$S$236,">0") -> 5 | K2: =E2/D2*1000 -> 12.630662 | L2: =IF(J2>=4,1,0) -> 1 | M2: =RANK(E2,$E$2:$E$48,0)+COUNTIF($E$2:E2,E2)-1 -> 1 | N2: =INDEX(Priority_List!$M$5:$M$51,MATCH($A2,Priority_List!$A$5:$A$51,0)) -> Tier 1: fix first
A3: ui_notifications | B3: UI | C3: JavaScript | D3: 7222 | E3: =SUMIFS(Data!$S$2:$S$236,Data!$A$2:$A$236,$A3) -> 25 | F3: =AVERAGEIFS(Data!$H$2:$H$236,Data!$A$2:$A$236,$A3) -> 12.63 | G3: =AVERAGEIFS(Data!$J$2:$J$236,Data!$A$2:$A$236,$A3) -> 808.79 | H3: =AVERAGEIFS(Data!$K$2:$K$236,Data!$A$2:$A$236,$A3) -> 33.14 | I3: =AVERAGEIFS(Data!$M$2:$M$236,Data!$A$2:$A$236,$A3) -> 5.2 | J3: =COUNTIFS(Data!$A$2:$A$236,$A3,Data!$S$2:$S$236,">0") -> 4 | K3: =E3/D3*1000 -> 3.461645 | L3: =IF(J3>=4,1,0) -> 1 | M3: =RANK(E3,$E$2:$E$48,0)+COUNTIF($E$2:E3,E3)-1 -> 2 | N3: =INDEX(Priority_List!$M$5:$M$51,MATCH($A3,Priority_List!$A$5:$A$51,0)) -> Tier 1: fix first
A4: ui_themes | B4: UI | C4: JavaScript | D4: 2559 | E4: =SUMIFS(Data!$S$2:$S$236,Data!$A$2:$A$236,$A4) -> 19 | F4: =AVERAGEIFS(Data!$H$2:$H$236,Data!$A$2:$A$236,$A4) -> 31.171 | G4: =AVERAGEIFS(Data!$J$2:$J$236,Data!$A$2:$A$236,$A4) -> 392.48 | H4: =AVERAGEIFS(Data!$K$2:$K$236,Data!$A$2:$A$236,$A4) -> 55.52 | I4: =AVERAGEIFS(Data!$M$2:$M$236,Data!$A$2:$A$236,$A4) -> 3.2 | J4: =COUNTIFS(Data!$A$2:$A$236,$A4,Data!$S$2:$S$236,">0") -> 4 | K4: =E4/D4*1000 -> 7.4247753 | L4: =IF(J4>=4,1,0) -> 1 | M4: =RANK(E4,$E$2:$E$48,0)+COUNTIF($E$2:E4,E4)-1 -> 3 | N4: =INDEX(Priority_List!$M$5:$M$51,MATCH($A4,Priority_List!$A$5:$A$51,0)) -> Tier 1: fix first
A5: auth_session | B5: Auth | C5: Python | D5: 3134 | E5: =SUMIFS(Data!$S$2:$S$236,Data!$A$2:$A$236,$A5) -> 17 | F5: =AVERAGEIFS(Data!$H$2:$H$236,Data!$A$2:$A$236,$A5) -> 20.78 | G5: =AVERAGEIFS(Data!$J$2:$J$236,Data!$A$2:$A$236,$A5) -> 481.88 | H5: =AVERAGEIFS(Data!$K$2:$K$236,Data!$A$2:$A$236,$A5) -> 36.74 | I5: =AVERAGEIFS(Data!$M$2:$M$236,Data!$A$2:$A$236,$A5) -> 4.4 | J5: =COUNTIFS(Data!$A$2:$A$236,$A5,Data!$S$2:$S$236,">0") -> 5 | K5: =E5/D5*1000 -> 5.4243778 | L5: =IF(J5>=4,1,0) -> 1 | M5: =RANK(E5,$E$2:$E$48,0)+COUNTIF($E$2:E5,E5)-1 -> 4 | N5: =INDEX(Priority_List!$M$5:$M$51,MATCH($A5,Priority_List!$A$5:$A$51,0)) -> Tier 1: fix first
A6: payments_fraud | B6: Payments | C6: Java | D6: 1821 | E6: =SUMIFS(Data!$S$2:$S$236,Data!$A$2:$A$236,$A6) -> 15 | F6: =AVERAGEIFS(Data!$H$2:$H$236,Data!$A$2:$A$236,$A6) -> 19.558 | G6: =AVERAGEIFS(Data!$J$2:$J$236,Data!$A$2:$A$236,$A6) -> 520.96 | H6: =AVERAGEIFS(Data!$K$2:$K$236,Data!$A$2:$A$236,$A6) -> 37.76 | I6: =AVERAGEIFS(Data!$M$2:$M$236,Data!$A$2:$A$236,$A6) -> 4 | J6: =COUNTIFS(Data!$A$2:$A$236,$A6,Data!$S$2:$S$236,">0") -> 4 | K6: =E6/D6*1000 -> 8.2372323 | L6: =IF(J6>=4,1,0) -> 1 | M6: =RANK(E6,$E$2:$E$48,0)+COUNTIF($E$2:E6,E6)-1 -> 5 | N6: =INDEX(Priority_List!$M$5:$M$51,MATCH($A6,Priority_List!$A$5:$A$51,0)) -> Tier 1: fix first
A7: reporting_audit_logs | B7: Reporting | C7: Java | D7: 3061 | E7: =SUMIFS(Data!$S$2:$S$236,Data!$A$2:$A$236,$A7) -> 14 | F7: =AVERAGEIFS(Data!$H$2:$H$236,Data!$A$2:$A$236,$A7) -> 22.64 | G7: =AVERAGEIFS(Data!$J$2:$J$236,Data!$A$2:$A$236,$A7) -> 559.24 | H7: =AVERAGEIFS(Data!$K$2:$K$236,Data!$A$2:$A$236,$A7) -> 63.26 | I7: =AVERAGEIFS(Data!$M$2:$M$236,Data!$A$2:$A$236,$A7) -> 4.6 | J7: =COUNTIFS(Data!$A$2:$A$236,$A7,Data!$S$2:$S$236,">0") -> 5 | K7: =E7/D7*1000 -> 4.5736687 | L7: =IF(J7>=4,1,0) -> 1 | M7: =RANK(E7,$E$2:$E$48,0)+COUNTIF($E$2:E7,E7)-1 -> 6 | N7: =INDEX(Priority_List!$M$5:$M$51,MATCH($A7,Priority_List!$A$5:$A$51,0)) -> Tier 1: fix first
A8: reporting_scheduler | B8: Reporting | C8: Java | D8: 1361 | E8: =SUMIFS(Data!$S$2:$S$236,Data!$A$2:$A$236,$A8) -> 13 | F8: =AVERAGEIFS(Data!$H$2:$H$236,Data!$A$2:$A$236,$A8) -> 27.748 | G8: =AVERAGEIFS(Data!$J$2:$J$236,Data!$A$2:$A$236,$A8) -> 262.51 | H8: =AVERAGEIFS(Data!$K$2:$K$236,Data!$A$2:$A$236,$A8) -> 41.03 | I8: =AVERAGEIFS(Data!$M$2:$M$236,Data!$A$2:$A$236,$A8) -> 4 | J8: =COUNTIFS(Data!$A$2:$A$236,$A8,Data!$S$2:$S$236,">0") -> 5 | K8: =E8/D8*1000 -> 9.5518001 | L8: =IF(J8>=4,1,0) -> 1 | M8: =RANK(E8,$E$2:$E$48,0)+COUNTIF($E$2:E8,E8)-1 -> 7 | N8: =INDEX(Priority_List!$M$5:$M$51,MATCH($A8,Priority_List!$A$5:$A$51,0)) -> Tier 1: fix first
A9: database_migration | B9: Database | C9: C++ | D9: 2891 | E9: =SUMIFS(Data!$S$2:$S$236,Data!$A$2:$A$236,$A9) -> 12 | F9: =AVERAGEIFS(Data!$H$2:$H$236,Data!$A$2:$A$236,$A9) -> 18.592 | G9: =AVERAGEIFS(Data!$J$2:$J$236,Data!$A$2:$A$236,$A9) -> 496.78 | H9: =AVERAGEIFS(Data!$K$2:$K$236,Data!$A$2:$A$236,$A9) -> 56.08 | I9: =AVERAGEIFS(Data!$M$2:$M$236,Data!$A$2:$A$236,$A9) -> 4.2 | J9: =COUNTIFS(Data!$A$2:$A$236,$A9,Data!$S$2:$S$236,">0") -> 5 | K9: =E9/D9*1000 -> 4.1508129 | L9: =IF(J9>=4,1,0) -> 1 | M9: =RANK(E9,$E$2:$E$48,0)+COUNTIF($E$2:E9,E9)-1 -> 8 | N9: =INDEX(Priority_List!$M$5:$M$51,MATCH($A9,Priority_List!$A$5:$A$51,0)) -> Tier 1: fix first
A10: payments_invoice | B10: Payments | C10: C++ | D10: 2645 | E10: =SUMIFS(Data!$S$2:$S$236,Data!$A$2:$A$236,$A10) -> 12 | F10: =AVERAGEIFS(Data!$H$2:$H$236,Data!$A$2:$A$236,$A10) -> 22.168 | G10: =AVERAGEIFS(Data!$J$2:$J$236,Data!$A$2:$A$236,$A10) -> 371.3 | H10: =AVERAGEIFS(Data!$K$2:$K$236,Data!$A$2:$A$236,$A10) -> 61.28 | I10: =AVERAGEIFS(Data!$M$2:$M$236,Data!$A$2:$A$236,$A10) -> 4.2 | J10: =COUNTIFS(Data!$A$2:$A$236,$A10,Data!$S$2:$S$236,">0") -> 4 | K10: =E10/D10*1000 -> 4.536862 | L10: =IF(J10>=4,1,0) -> 1 | M10: =RANK(E10,$E$2:$E$48,0)+COUNTIF($E$2:E10,E10)-1 -> 9 | N10: =INDEX(Priority_List!$M$5:$M$51,MATCH($A10,Priority_List!$A$5:$A$51,0)) -> Tier 3: monitor
A11: database_replication | B11: Database | C11: C++ | D11: 989 | E11: =SUMIFS(Data!$S$2:$S$236,Data!$A$2:$A$236,$A11) -> 10 | F11: =AVERAGEIFS(Data!$H$2:$H$236,Data!$A$2:$A$236,$A11) -> 19.548 | G11: =AVERAGEIFS(Data!$J$2:$J$236,Data!$A$2:$A$236,$A11) -> 328.14 | H11: =AVERAGEIFS(Data!$K$2:$K$236,Data!$A$2:$A$236,$A11) -> 65.82 | I11: =AVERAGEIFS(Data!$M$2:$M$236,Data!$A$2:$A$236,$A11) -> 3 | J11: =COUNTIFS(Data!$A$2:$A$236,$A11,Data!$S$2:$S$236,">0") -> 5 | K11: =E11/D11*1000 -> 10.111223 | L11: =IF(J11>=4,1,0) -> 1 | M11: =RANK(E11,$E$2:$E$48,0)+COUNTIF($E$2:E11,E11)-1 -> 10 | N11: =INDEX(Priority_List!$M$5:$M$51,MATCH($A11,Priority_List!$A$5:$A$51,0)) -> Tier 3: monitor
A12: payments_gateway | B12: Payments | C12: Java | D12: 1124 | E12: =SUMIFS(Data!$S$2:$S$236,Data!$A$2:$A$236,$A12) -> 7 | F12: =AVERAGEIFS(Data!$H$2:$H$236,Data!$A$2:$A$236,$A12) -> 26.348 | G12: =AVERAGEIFS(Data!$J$2:$J$236,Data!$A$2:$A$236,$A12) -> 273.64 | H12: =AVERAGEIFS(Data!$K$2:$K$236,Data!$A$2:$A$236,$A12) -> 59.06 | I12: =AVERAGEIFS(Data!$M$2:$M$236,Data!$A$2:$A$236,$A12) -> 2.8 | J12: =COUNTIFS(Data!$A$2:$A$236,$A12,Data!$S$2:$S$236,">0") -> 4 | K12: =E12/D12*1000 -> 6.227758 | L12: =IF(J12>=4,1,0) -> 1 | M12: =RANK(E12,$E$2:$E$48,0)+COUNTIF($E$2:E12,E12)-1 -> 11 | N12: =INDEX(Priority_List!$M$5:$M$51,MATCH($A12,Priority_List!$A$5:$A$51,0)) -> Tier 2: watch closely
A13: reporting_export | B13: Reporting | C13: Java | D13: 1649 | E13: =SUMIFS(Data!$S$2:$S$236,Data!$A$2:$A$236,$A13) -> 7 | F13: =AVERAGEIFS(Data!$H$2:$H$236,Data!$A$2:$A$236,$A13) -> 16.384 | G13: =AVERAGEIFS(Data!$J$2:$J$236,Data!$A$2:$A$236,$A13) -> 279.64 | H13: =AVERAGEIFS(Data!$K$2:$K$236,Data!$A$2:$A$236,$A13) -> 66.02 | I13: =AVERAGEIFS(Data!$M$2:$M$236,Data!$A$2:$A$236,$A13) -> 3.4 | J13: =COUNTIFS(Data!$A$2:$A$236,$A13,Data!$S$2:$S$236,">0") -> 4 | K13: =E13/D13*1000 -> 4.244997 | L13: =IF(J13>=4,1,0) -> 1 | M13: =RANK(E13,$E$2:$E$48,0)+COUNTIF($E$2:E13,E13)-1 -> 12 | N13: =INDEX(Priority_List!$M$5:$M$51,MATCH($A13,Priority_List!$A$5:$A$51,0)) -> Tier 1: fix first
... A48: reporting_aggregator | B48: Reporting | C48: Java | D48: 1634 | E48: =SUMIFS(Data!$S$2:$S$236,Data!$A$2:$A$236,$A48) -> 0 | F48: =AVERAGEIFS(Data!$H$2:$H$236,Data!$A$2:$A$236,$A48) -> 11.074 | G48: =AVERAGEIFS(Data!$J$2:$J$236,Data!$A$2:$A$236,$A48) -> 188.9 | H48: =AVERAGEIFS(Data!$K$2:$K$236,Data!$A$2:$A$236,$A48) -> 86.1 | I48: =AVERAGEIFS(Data!$M$2:$M$236,Data!$A$2:$A$236,$A48) -> 2.6 | J48: =COUNTIFS(Data!$A$2:$A$236,$A48,Data!$S$2:$S$236,">0") -> 0 | K48: =E48/D48*1000 -> 0 | L48: =IF(J48>=4,1,0) -> 0 | M48: =RANK(E48,$E$2:$E$48,0)+COUNTIF($E$2:E48,E48)-1 -> 47 | N48: =INDEX(Priority_List!$M$5:$M$51,MATCH($A48,Priority_List!$A$5:$A$51,0)) -> Tier 3: monitor

Sheet Data
A1: module | B1: component | C1: language | D1: release | E1: release_date | F1: release_index | G1: size | H1: complexity | I1: coupling | J1: churn | K1: test_coverage | L1: commit_count | M1: contributors | N1: changed_lines | O1: defects_low | P1: defects_medium | Q1: defects_high | R1: defects_critical | S1: total_defects | T1: churn_per_commit | U1: defect_density | V1: high_severity_defects | W1: risk_score | X1: defects_prev_release | Y1: repeat_defect_flag | Z1: high_defect | AA1: complexity_outlier | AB1: complexity_band | AC1: churn_band | AD1: coverage_band | AE1: contributor_group
A2: api_docs | B2: API | C2: Python | D2: v1.0 | E2: 45306 | F2: 1 | G2: 2376 | H2: 14.43 | I2: 10.44 | J2: 159.9 | K2: 89.9 | L2: 5 | M2: 3 | N2: 204 | O2: 0 | P2: 0 | Q2: 0 | R2: 0 | S2: =SUM(O2:R2) -> 0 | T2: =J2/L2 -> 31.98 | U2: =S2/G2*1000 -> 0 | V2: =Q2+R2 -> 0 | W2: =100*((J2-MIN($J$2:$J$236))/(MAX($J$2:$J$236)-MIN($J$2:$J$236))+(H2-MIN($H$2:$H$236))/(MAX($H$2:$H$236)-MIN($H$2:$H$236))+(1-(K2-MIN($K$2:$K$236))/(MAX($K$2:$K$236)-MIN($K$2:$K$236))))/3 -> 20.349183 | X2: 0 | Y2: 0 | Z2: 0 | AA2: No | AB2: =IF(H2<=Complexity!$C$11,"Q1 (lowest)",IF(H2<=Complexity!$C$12,"Q2",IF(H2<=Complexity!$C$13,"Q3","Q4 (highest)"))) -> Q2 | AC2: =IF(J2<=Churn!$C$11,"Q1 (lowest)",IF(J2<=Churn!$C$12,"Q2",IF(J2<=Churn!$C$13,"Q3","Q4 (highest)"))) -> Q1 (lowest) | AD2: =IF(K2<=40,"<=40%",IF(K2<=60,"40-60%",IF(K2<=80,"60-80%","80%+"))) -> 80%+ | AE2: =IF(M2<=2,"1-2",IF(M2<=4,"3-4",IF(M2<=6,"5-6","7+"))) -> 3-4
A3: api_docs | B3: API | C3: Python | D3: v1.1 | E3: 45432 | F3: 2 | G3: 2376 | H3: 13.595 | I3: 5.53 | J3: 373.1 | K3: 88.3 | L3: 12 | M3: 5 | N3: 459 | O3: 0 | P3: 0 | Q3: 0 | R3: 0 | S3: =SUM(O3:R3) -> 0 | T3: =J3/L3 -> 31.091667 | U3: =S3/G3*1000 -> 0 | V3: =Q3+R3 -> 0 | W3: =100*((J3-MIN($J$2:$J$236))/(MAX($J$2:$J$236)-MIN($J$2:$J$236))+(H3-MIN($H$2:$H$236))/(MAX($H$2:$H$236)-MIN($H$2:$H$236))+(1-(K3-MIN($K$2:$K$236))/(MAX($K$2:$K$236)-MIN($K$2:$K$236))))/3 -> 26.038106 | X3: 0 | Y3: 0 | Z3: 0 | AA3: No | AB3: =IF(H3<=Complexity!$C$11,"Q1 (lowest)",IF(H3<=Complexity!$C$12,"Q2",IF(H3<=Complexity!$C$13,"Q3","Q4 (highest)"))) -> Q2 | AC3: =IF(J3<=Churn!$C$11,"Q1 (lowest)",IF(J3<=Churn!$C$12,"Q2",IF(J3<=Churn!$C$13,"Q3","Q4 (highest)"))) -> Q3 | AD3: =IF(K3<=40,"<=40%",IF(K3<=60,"40-60%",IF(K3<=80,"60-80%","80%+"))) -> 80%+ | AE3: =IF(M3<=2,"1-2",IF(M3<=4,"3-4",IF(M3<=6,"5-6","7+"))) -> 5-6
A4: api_docs | B4: API | C4: Python | D4: v2.0 | E4: 45545 | F4: 3 | G4: 2376 | H4: 12.76 | I4: 9.97 | J4: 266.5 | K4: 93.1 | L4: 12 | M4: 3 | N4: 557 | O4: 0 | P4: 0 | Q4: 0 | R4: 0 | S4: =SUM(O4:R4) -> 0 | T4: =J4/L4 -> 22.208333 | U4: =S4/G4*1000 -> 0 | V4: =Q4+R4 -> 0 | W4: =100*((J4-MIN($J$2:$J$236))/(MAX($J$2:$J$236)-MIN($J$2:$J$236))+(H4-MIN($H$2:$H$236))/(MAX($H$2:$H$236)-MIN($H$2:$H$236))+(1-(K4-MIN($K$2:$K$236))/(MAX($K$2:$K$236)-MIN($K$2:$K$236))))/3 -> 20.040041 | X4: 0 | Y4: 0 | Z4: 0 | AA4: No | AB4: =IF(H4<=Complexity!$C$11,"Q1 (lowest)",IF(H4<=Complexity!$C$12,"Q2",IF(H4<=Complexity!$C$13,"Q3","Q4 (highest)"))) -> Q2 | AC4: =IF(J4<=Churn!$C$11,"Q1 (lowest)",IF(J4<=Churn!$C$12,"Q2",IF(J4<=Churn!$C$13,"Q3","Q4 (highest)"))) -> Q2 | AD4: =IF(K4<=40,"<=40%",IF(K4<=60,"40-60%",IF(K4<=80,"60-80%","80%+"))) -> 80%+ | AE4: =IF(M4<=2,"1-2",IF(M4<=4,"3-4",IF(M4<=6,"5-6","7+"))) -> 3-4
A5: api_docs | B5: API | C5: Python | D5: v2.1 | E5: 45706 | F5: 4 | G5: 2376 | H5: 19.7 | I5: 11.34 | J5: 84.6 | K5: 91 | L5: 3 | M5: 2 | N5: 113 | O5: 0 | P5: 0 | Q5: 0 | R5: 0 | S5: =SUM(O5:R5) -> 0 | T5: =J5/L5 -> 28.2 | U5: =S5/G5*1000 -> 0 | V5: =Q5+R5 -> 0 | W5: =100*((J5-MIN($J$2:$J$236))/(MAX($J$2:$J$236)-MIN($J$2:$J$236))+(H5-MIN($H$2:$H$236))/(MAX($H$2:$H$236)-MIN($H$2:$H$236))+(1-(K5-MIN($K$2:$K$236))/(MAX($K$2:$K$236)-MIN($K$2:$K$236))))/3 -> 23.377413 | X5: 0 | Y5: 0 | Z5: 0 | AA5: No | AB5: =IF(H5<=Complexity!$C$11,"Q1 (lowest)",IF(H5<=Complexity!$C$12,"Q2",IF(H5<=Complexity!$C$13,"Q3","Q4 (highest)"))) -> Q4 (highest) | AC5: =IF(J5<=Churn!$C$11,"Q1 (lowest)",IF(J5<=Churn!$C$12,"Q2",IF(J5<=Churn!$C$13,"Q3","Q4 (highest)"))) -> Q1 (lowest) | AD5: =IF(K5<=40,"<=40%",IF(K5<=60,"40-60%",IF(K5<=80,"60-80%","80%+"))) -> 80%+ | AE5: =IF(M5<=2,"1-2",IF(M5<=4,"3-4",IF(M5<=6,"5-6","7+"))) -> 1-2
A6: api_docs | B6: API | C6: Python | D6: v3.0 | E6: 45839 | F6: 5 | G6: 2376 | H6: 10.27 | I6: 10.94 | J6: 1161.8 | K6: 87.4 | L6: 32 | M6: 8 | N6: 1771 | O6: 1 | P6: 2 | Q6: 0 | R6: 1 | S6: =SUM(O6:R6) -> 4 | T6: =J6/L6 -> 36.30625 | U6: =S6/G6*1000 -> 1.6835017 | V6: =Q6+R6 -> 1 | W6: =100*((J6-MIN($J$2:$J$236))/(MAX($J$2:$J$236)-MIN($J$2:$J$236))+(H6-MIN($H$2:$H$236))/(MAX($H$2:$H$236)-MIN($H$2:$H$236))+(1-(K6-MIN($K$2:$K$236))/(MAX($K$2:$K$236)-MIN($K$2:$K$236))))/3 -> 44.54418 | X6: 0 | Y6: 0 | Z6: 1 | AA6: No | AB6: =IF(H6<=Complexity!$C$11,"Q1 (lowest)",IF(H6<=Complexity!$C$12,"Q2",IF(H6<=Complexity!$C$13,"Q3","Q4 (highest)"))) -> Q1 (lowest) | AC6: =IF(J6<=Churn!$C$11,"Q1 (lowest)",IF(J6<=Churn!$C$12,"Q2",IF(J6<=Churn!$C$13,"Q3","Q4 (highest)"))) -> Q4 (highest) | AD6: =IF(K6<=40,"<=40%",IF(K6<=60,"40-60%",IF(K6<=80,"60-80%","80%+"))) -> 80%+ | AE6: =IF(M6<=2,"1-2",IF(M6<=4,"3-4",IF(M6<=6,"5-6","7+"))) -> 7+
A7: api_gateway | B7: API | C7: Java | D7: v1.0 | E7: 45306 | F7: 1 | G7: 2296 | H7: 22.02 | I7: 15.16 | J7: 1249.4 | K7: 37 | L7: 59 | M7: 9 | N7: 1964 | O7: 7 | P7: 3 | Q7: 2 | R7: 3 | S7: =SUM(O7:R7) -> 15 | T7: =J7/L7 -> 21.176271 | U7: =S7/G7*1000 -> 6.533101 | V7: =Q7+R7 -> 5 | W7: =100*((J7-MIN($J$2:$J$236))/(MAX($J$2:$J$236)-MIN($J$2:$J$236))+(H7-MIN($H$2:$H$236))/(MAX($H$2:$H$236)-MIN($H$2:$H$236))+(1-(K7-MIN($K$2:$K$236))/(MAX($K$2:$K$236)-MIN($K$2:$K$236))))/3 -> 82.401765 | X7: 0 | Y7: 1 | Z7: 1 | AA7: No | AB7: =IF(H7<=Complexity!$C$11,"Q1 (lowest)",IF(H7<=Complexity!$C$12,"Q2",IF(H7<=Complexity!$C$13,"Q3","Q4 (highest)"))) -> Q4 (highest) | AC7: =IF(J7<=Churn!$C$11,"Q1 (lowest)",IF(J7<=Churn!$C$12,"Q2",IF(J7<=Churn!$C$13,"Q3","Q4 (highest)"))) -> Q4 (highest) | AD7: =IF(K7<=40,"<=40%",IF(K7<=60,"40-60%",IF(K7<=80,"60-80%","80%+"))) -> <=40% | AE7: =IF(M7<=2,"1-2",IF(M7<=4,"3-4",IF(M7<=6,"5-6","7+"))) -> 7+
A8: api_gateway | B8: API | C8: Java | D8: v1.1 | E8: 45432 | F8: 2 | G8: 2296 | H8: 15.56 | I8: 10.71 | J8: 178 | K8: 37.7 | L8: 5 | M8: 2 | N8: 299 | O8: 0 | P8: 1 | Q8: 1 | R8: 0 | S8: =SUM(O8:R8) -> 2 | T8: =J8/L8 -> 35.6 | U8: =S8/G8*1000 -> 0.87108014 | V8: =Q8+R8 -> 1 | W8: =100*((J8-MIN($J$2:$J$236))/(MAX($J$2:$J$236)-MIN($J$2:$J$236))+(H8-MIN($H$2:$H$236))/(MAX($H$2:$H$236)-MIN($H$2:$H$236))+(1-(K8-MIN($K$2:$K$236))/(MAX($K$2:$K$236)-MIN($K$2:$K$236))))/3 -> 45.848053 | X8: 15 | Y8: 1 | Z8: 0 | AA8: No | AB8: =IF(H8<=Complexity!$C$11,"Q1 (lowest)",IF(H8<=Complexity!$C$12,"Q2",IF(H8<=Complexity!$C$13,"Q3","Q4 (highest)"))) -> Q3 | AC8: =IF(J8<=Churn!$C$11,"Q1 (lowest)",IF(J8<=Churn!$C$12,"Q2",IF(J8<=Churn!$C$13,"Q3","Q4 (highest)"))) -> Q2 | AD8: =IF(K8<=40,"<=40%",IF(K8<=60,"40-60%",IF(K8<=80,"60-80%","80%+"))) -> <=40% | AE8: =IF(M8<=2,"1-2",IF(M8<=4,"3-4",IF(M8<=6,"5-6","7+"))) -> 1-2
A9: api_gateway | B9: API | C9: Java | D9: v2.0 | E9: 45545 | F9: 3 | G9: 2296 | H9: 23.84 | I9: 16.97 | J9: 568.9 | K9: 44.5 | L9: 18 | M9: 4 | N9: 654 | O9: 2 | P9: 3 | Q9: 1 | R9: 0 | S9: =SUM(O9:R9) -> 6 | T9: =J9/L9 -> 31.605556 | U9: =S9/G9*1000 -> 2.6132404 | V9: =Q9+R9 -> 1 | W9: =100*((J9-MIN($J$2:$J$236))/(MAX($J$2:$J$236)-MIN($J$2:$J$236))+(H9-MIN($H$2:$H$236))/(MAX($H$2:$H$236)-MIN($H$2:$H$236))+(1-(K9-MIN($K$2:$K$236))/(MAX($K$2:$K$236)-MIN($K$2:$K$236))))/3 -> 62.255191 | X9: 2 | Y9: 1 | Z9: 1 | AA9: No | AB9: =IF(H9<=Complexity!$C$11,"Q1 (lowest)",IF(H9<=Complexity!$C$12,"Q2",IF(H9<=Complexity!$C$13,"Q3","Q4 (highest)"))) -> Q4 (highest) | AC9: =IF(J9<=Churn!$C$11,"Q1 (lowest)",IF(J9<=Churn!$C$12,"Q2",IF(J9<=Churn!$C$13,"Q3","Q4 (highest)"))) -> Q4 (highest) | AD9: =IF(K9<=40,"<=40%",IF(K9<=60,"40-60%",IF(K9<=80,"60-80%","80%+"))) -> 40-60% | AE9: =IF(M9<=2,"1-2",IF(M9<=4,"3-4",IF(M9<=6,"5-6","7+"))) -> 3-4
